<?xml version="1.0"?>
<robot xmlns:sensor="http://playerstage.sourceforge.net/gazebo/xmlschema/#sensor"
       xmlns:controller="http://playerstage.sourceforge.net/gazebo/xmlschema/#controller"
       xmlns:interface="http://playerstage.sourceforge.net/gazebo/xmlschema/#interface"
       xmlns:xacro="http://playerstage.sourceforge.net/gazebo/xmlschema/#interface"
       name="rocketbox_male" >

    <material name="Blue">
      <color rgba="0.0 0.0 0.8 1.0"/>
    </material>
    <material name="Green">
      <color rgba="0.0 0.8 0.0 1.0"/>
    </material>
    <material name="Grey">
      <color rgba="0.7 0.7 0.7 1.0"/>
    </material>
    <material name="Grey2">
      <color rgba="0.9 0.9 0.9 1.0"/>
    </material>
    <material name="Red">
      <color rgba="0.8 0.0 0.0 1.0"/>
    </material>
    <material name="White">
      <color rgba="1.0 1.0 1.0 1.0"/>
    </material>
    <material name="Black">
      <color rgba="0.1 0.1 0.1 1.0"/>
    </material>
    <material name="LightGrey">
      <color rgba="0.6 0.6 0.6 1.0"/>
    </material>

    <link name="root_link"/>
      <link name="base_prismatic_dummy1">
        <visual>
          <origin rpy="0 0 0" xyz="0 0 0"/>
          <geometry>
            <box size="0.001 0.001 0.001"/>
          </geometry>
          <material name="Blue"/>
        </visual>
      </link>
      <link name="base_prismatic_dummy2">
        <visual>
          <origin rpy="0 0 0" xyz="0 0 0"/>
          <geometry>
            <box size="0.001 0.001 0.001"/>
          </geometry>
          <material name="Blue"/>
        </visual>
      </link>
      <link name="base_prismatic_dummy3">
        <visual>
          <origin rpy="0 0 0" xyz="0 0 0"/>
          <geometry>
            <box size="0.001 0.001 0.001"/>
          </geometry>
          <material name="Blue"/>
        </visual>
      </link>
      <link name="base_revolute_dummy1">
        <visual>
          <origin rpy="0 0 0" xyz="0 0 0"/>
          <geometry>
            <box size="0.001 0.001 0.001"/>
          </geometry>
          <material name="Blue"/>
        </visual>
      </link>
      <link name="base_revolute_dummy2">
        <visual>
          <origin rpy="0 0 0" xyz="0 0 0"/>
          <geometry>
            <box size="0.001 0.001 0.001"/>
          </geometry>
          <material name="Blue"/>
        </visual>
      </link>
      <joint name="base_prismatic_joint_x" type="prismatic">
        <axis xyz="1 0 0"/>
        <limit effort="10000" lower ="-5.0" upper="5.0" velocity ="0.6"/>
        <origin rpy="0 0 0" xyz="0 0 1.1713"/>
        <parent link="root_link"/>
        <child link="base_prismatic_dummy1"/>
      </joint>
      <joint name="base_prismatic_joint_y" type="prismatic">
        <axis xyz="0 1 0"/>
        <limit effort="10000" lower ="-5.0" upper="5.0" velocity ="0.6"/>
        <origin rpy="0 0 0" xyz="0 0 0"/>
        <parent link="base_prismatic_dummy1"/>
        <child link="base_prismatic_dummy2"/>
      </joint>
      <joint name="base_prismatic_joint_z" type="prismatic">
        <axis xyz="0 0 1"/>
        <limit effort="10000" lower ="-5.0" upper="5.0" velocity ="0.6"/>
        <origin rpy="0 0 0" xyz="0 0 0"/>
        <parent link="base_prismatic_dummy2"/>
        <child link="base_prismatic_dummy3"/>
      </joint>
      <joint name="base_revolute_joint_x" type="continuous">
        <axis xyz="1 0 0"/>
        <origin rpy="0 0 0" xyz="0 0 0"/>
        <parent link="base_prismatic_dummy3"/>
        <child link="base_revolute_dummy1"/>
      </joint>
      <joint name="base_revolute_joint_y" type="continuous">
        <axis xyz="0 1 0"/>
        <origin rpy="0 0 0" xyz="0 0 0"/>
        <parent link="base_revolute_dummy1"/>
        <child link="base_revolute_dummy2"/>
      </joint>
      <joint name="base_revolute_joint_z" type="continuous">
        <axis xyz="0 0 1"/>
        <origin rpy="0 0 0" xyz="0 0 0"/>
        <parent link="base_revolute_dummy2"/>
        <child link="pelvis_link"/>
      </joint>
      <link name="pelvis_link"/>
      <link name="Spine_z_link"/>
      <link name="Spine_y_link"/>
      <link name="Spine_x_link">
        <visual>
          <origin rpy="0 0 0" xyz="0 0 0"/>
          <geometry>
            <mesh filename="../rami/modelinria/Spine.obj"/>
          </geometry>
          <material name="Blue"/>
        </visual>
        <collision>
          <origin rpy="0 0 0" xyz="0 0 0"/>
          <geometry>
            <mesh filename="../rami/modelinria/Spine.obj"/>
          </geometry>
        </collision>
      </link>
      <joint name="Spine_z_joint" type ="revolute">
          <axis xyz="0 0 1"/>
          <limit effort="10000" lower ="-3.14" upper="3.14" velocity ="0.6"/>
          <origin rpy="0 0 0" xyz="0 0 0.909008"/>
          <parent link="pelvis_link"/>
          <child link="Spine_z_link"/>
      </joint>
      <joint name="Spine_y_joint" type ="revolute">
          <axis xyz="0 1 0"/>
          <limit effort="10000" lower ="-3.14" upper="3.14" velocity ="0.6"/>
          <origin rpy="0 0 0" xyz="0 0 0"/>
          <parent link="Spine_z_link"/>
          <child link="Spine_y_link"/>
      </joint>
      <joint name="Spine_x_joint" type ="revolute">
          <axis xyz="1 0 0"/>
          <limit effort="10000" lower ="-3.14" upper="3.14" velocity ="0.6"/>
          <origin rpy="0 0 0" xyz="0 0 0"/>
          <parent link="Spine_y_link"/>
          <child link="Spine_x_link"/>
      </joint>
      <link name="Head_z_link"/>
      <link name="Head_y_link"/>
      <link name="Head_x_link">
        <visual>
          <origin rpy="0 0 0" xyz="0 0 0"/>
          <geometry>
            <mesh filename="../rami/modelinria/Head.obj"/>
          </geometry>
          <material name="Blue"/>
        </visual>
        <collision>
          <origin rpy="0 0 0" xyz="0 0 0"/>
          <geometry>
            <mesh filename="../rami/modelinria/Head.obj"/>
          </geometry>
        </collision>
      </link>
      <joint name="Head_z_joint" type ="revolute">
          <axis xyz="0 0 1"/>
          <limit effort="10000" lower ="-3.14" upper="3.14" velocity ="0.6"/>
          <origin rpy="0 0 0" xyz="0 0 1.59751"/>
          <parent link="Spine_x_link"/>
          <child link="Head_z_link"/>
      </joint>
      <joint name="Head_y_joint" type ="revolute">
          <axis xyz="0 1 0"/>
          <limit effort="10000" lower ="-3.14" upper="3.14" velocity ="0.6"/>
          <origin rpy="0 0 0" xyz="0 0 0"/>
          <parent link="Head_z_link"/>
          <child link="Head_y_link"/>
      </joint>
      <joint name="Head_x_joint" type ="revolute">
          <axis xyz="1 0 0"/>
          <limit effort="10000" lower ="-3.14" upper="3.14" velocity ="0.6"/>
          <origin rpy="0 0 0" xyz="0 0 0"/>
          <parent link="Head_y_link"/>
          <child link="Head_x_link"/>
      </joint>
      <link name="Headendsite_z_link"/>
      <link name="Headendsite_y_link"/>
      <link name="Headendsite_x_link">
        <visual>
          <origin rpy="0 0 0" xyz="0 0 0"/>
          <geometry>
            <mesh filename="../rami/modelinria/Headendsite.obj"/>
          </geometry>
          <material name="Blue"/>
        </visual>
        <collision>
          <origin rpy="0 0 0" xyz="0 0 0"/>
          <geometry>
            <mesh filename="../rami/modelinria/Headendsite.obj"/>
          </geometry>
        </collision>
      </link>
      <joint name="Headendsite_z_joint" type ="revolute">
          <axis xyz="0 0 1"/>
          <limit effort="10000" lower ="-3.14" upper="3.14" velocity ="0.6"/>
          <origin rpy="0 0 0" xyz="0 0 0.452755"/>
          <parent link="Head_x_link"/>
          <child link="Headendsite_z_link"/>
      </joint>
      <joint name="Headendsite_y_joint" type ="revolute">
          <axis xyz="0 1 0"/>
          <limit effort="10000" lower ="-3.14" upper="3.14" velocity ="0.6"/>
          <origin rpy="0 0 0" xyz="0 0 0"/>
          <parent link="Headendsite_z_link"/>
          <child link="Headendsite_y_link"/>
      </joint>
      <joint name="Headendsite_x_joint" type ="revolute">
          <axis xyz="1 0 0"/>
          <limit effort="10000" lower ="-3.14" upper="3.14" velocity ="0.6"/>
          <origin rpy="0 0 0" xyz="0 0 0"/>
          <parent link="Headendsite_y_link"/>
          <child link="Headendsite_x_link"/>
      </joint>
      <link name="LeftShoulder_z_link"/>
      <link name="LeftShoulder_y_link"/>
      <link name="LeftShoulder_x_link">
        <visual>
          <origin rpy="0 0 0" xyz="0 0 0"/>
          <geometry>
            <mesh filename="../rami/modelinria/LeftShoulder.obj"/>
          </geometry>
          <material name="Blue"/>
        </visual>
        <collision>
          <origin rpy="0 0 0" xyz="0 0 0"/>
          <geometry>
            <mesh filename="../rami/modelinria/LeftShoulder.obj"/>
          </geometry>
        </collision>
      </link>
      <joint name="LeftShoulder_z_joint" type ="revolute">
          <axis xyz="0 0 1"/>
          <limit effort="10000" lower ="-3.14" upper="3.14" velocity ="0.6"/>
          <origin rpy="0 0 0" xyz="0 0 1.25984"/>
          <parent link="Spine_x_link"/>
          <child link="LeftShoulder_z_link"/>
      </joint>
      <joint name="LeftShoulder_y_joint" type ="revolute">
          <axis xyz="0 1 0"/>
          <limit effort="10000" lower ="-3.14" upper="3.14" velocity ="0.6"/>
          <origin rpy="0 0 0" xyz="0 0 0"/>
          <parent link="LeftShoulder_z_link"/>
          <child link="LeftShoulder_y_link"/>
      </joint>
      <joint name="LeftShoulder_x_joint" type ="revolute">
          <axis xyz="1 0 0"/>
          <limit effort="10000" lower ="-3.14" upper="3.14" velocity ="0.6"/>
          <origin rpy="0 0 0" xyz="0 0 0"/>
          <parent link="LeftShoulder_y_link"/>
          <child link="LeftShoulder_x_link"/>
      </joint>
      <link name="LeftArm_z_link"/>
      <link name="LeftArm_y_link"/>
      <link name="LeftArm_x_link">
        <visual>
          <origin rpy="0 0 0" xyz="0 0 0"/>
          <geometry>
            <mesh filename="../rami/modelinria/LeftArm.obj"/>
          </geometry>
          <material name="Blue"/>
        </visual>
        <collision>
          <origin rpy="0 0 0" xyz="0 0 0"/>
          <geometry>
            <mesh filename="../rami/modelinria/LeftArm.obj"/>
          </geometry>
        </collision>
      </link>
      <joint name="LeftArm_z_joint" type ="revolute">
          <axis xyz="0 0 1"/>
          <limit effort="10000" lower ="-3.14" upper="3.14" velocity ="0.6"/>
          <origin rpy="0 0 0" xyz="-0.7874 0 0"/>
          <parent link="LeftShoulder_x_link"/>
          <child link="LeftArm_z_link"/>
      </joint>
      <joint name="LeftArm_y_joint" type ="revolute">
          <axis xyz="0 1 0"/>
          <limit effort="10000" lower ="-3.14" upper="3.14" velocity ="0.6"/>
          <origin rpy="0 0 0" xyz="0 0 0"/>
          <parent link="LeftArm_z_link"/>
          <child link="LeftArm_y_link"/>
      </joint>
      <joint name="LeftArm_x_joint" type ="revolute">
          <axis xyz="1 0 0"/>
          <limit effort="10000" lower ="-3.14" upper="3.14" velocity ="0.6"/>
          <origin rpy="0 0 0" xyz="0 0 0"/>
          <parent link="LeftArm_y_link"/>
          <child link="LeftArm_x_link"/>
      </joint>
      <link name="LeftForeArm_z_link"/>
      <link name="LeftForeArm_y_link"/>
      <link name="LeftForeArm_x_link">
        <visual>
          <origin rpy="0 0 0" xyz="0 0 0"/>
          <geometry>
            <mesh filename="../rami/modelinria/LeftForeArm.obj"/>
          </geometry>
          <material name="Blue"/>
        </visual>
        <collision>
          <origin rpy="0 0 0" xyz="0 0 0"/>
          <geometry>
            <mesh filename="../rami/modelinria/LeftForeArm.obj"/>
          </geometry>
        </collision>
      </link>
      <joint name="LeftForeArm_z_joint" type ="revolute">
          <axis xyz="0 0 1"/>
          <limit effort="10000" lower ="-3.14" upper="3.14" velocity ="0.6"/>
          <origin rpy="0 0 0" xyz="-1.29921 0 0"/>
          <parent link="LeftArm_x_link"/>
          <child link="LeftForeArm_z_link"/>
      </joint>
      <joint name="LeftForeArm_y_joint" type ="revolute">
          <axis xyz="0 1 0"/>
          <limit effort="10000" lower ="-3.14" upper="3.14" velocity ="0.6"/>
          <origin rpy="0 0 0" xyz="0 0 0"/>
          <parent link="LeftForeArm_z_link"/>
          <child link="LeftForeArm_y_link"/>
      </joint>
      <joint name="LeftForeArm_x_joint" type ="revolute">
          <axis xyz="1 0 0"/>
          <limit effort="10000" lower ="-3.14" upper="3.14" velocity ="0.6"/>
          <origin rpy="0 0 0" xyz="0 0 0"/>
          <parent link="LeftForeArm_y_link"/>
          <child link="LeftForeArm_x_link"/>
      </joint>
      <link name="LeftHand_z_link"/>
      <link name="LeftHand_y_link"/>
      <link name="LeftHand_x_link">
        <visual>
          <origin rpy="0 0 0" xyz="0 0 0"/>
          <geometry>
            <mesh filename="../rami/modelinria/LeftHand.obj"/>
          </geometry>
          <material name="Blue"/>
        </visual>
        <collision>
          <origin rpy="0 0 0" xyz="0 0 0"/>
          <geometry>
            <mesh filename="../rami/modelinria/LeftHand.obj"/>
          </geometry>
        </collision>
      </link>
      <joint name="LeftHand_z_joint" type ="revolute">
          <axis xyz="0 0 1"/>
          <limit effort="10000" lower ="-3.14" upper="3.14" velocity ="0.6"/>
          <origin rpy="0 0 0" xyz="-1.03081 0 0"/>
          <parent link="LeftForeArm_x_link"/>
          <child link="LeftHand_z_link"/>
      </joint>
      <joint name="LeftHand_y_joint" type ="revolute">
          <axis xyz="0 1 0"/>
          <limit effort="10000" lower ="-3.14" upper="3.14" velocity ="0.6"/>
          <origin rpy="0 0 0" xyz="0 0 0"/>
          <parent link="LeftHand_z_link"/>
          <child link="LeftHand_y_link"/>
      </joint>
      <joint name="LeftHand_x_joint" type ="revolute">
          <axis xyz="1 0 0"/>
          <limit effort="10000" lower ="-3.14" upper="3.14" velocity ="0.6"/>
          <origin rpy="0 0 0" xyz="0 0 0"/>
          <parent link="LeftHand_y_link"/>
          <child link="LeftHand_x_link"/>
      </joint>
      <link name="LeftHandPinky1_z_link"/>
      <link name="LeftHandPinky1_y_link"/>
      <link name="LeftHandPinky1_x_link">
        <visual>
          <origin rpy="0 0 0" xyz="0 0 0"/>
          <geometry>
            <mesh filename="../rami/modelinria/LeftHandPinky1.obj"/>
          </geometry>
          <material name="Blue"/>
        </visual>
        <collision>
          <origin rpy="0 0 0" xyz="0 0 0"/>
          <geometry>
            <mesh filename="../rami/modelinria/LeftHandPinky1.obj"/>
          </geometry>
        </collision>
      </link>
      <joint name="LeftHandPinky1_z_joint" type ="revolute">
          <axis xyz="0 0 1"/>
          <limit effort="10000" lower ="-3.14" upper="3.14" velocity ="0.6"/>
          <origin rpy="0 0 0" xyz="-0.281979 -0.013815 0"/>
          <parent link="LeftHand_x_link"/>
          <child link="LeftHandPinky1_z_link"/>
      </joint>
      <joint name="LeftHandPinky1_y_joint" type ="revolute">
          <axis xyz="0 1 0"/>
          <limit effort="10000" lower ="-3.14" upper="3.14" velocity ="0.6"/>
          <origin rpy="0 0 0" xyz="0 0 0"/>
          <parent link="LeftHandPinky1_z_link"/>
          <child link="LeftHandPinky1_y_link"/>
      </joint>
      <joint name="LeftHandPinky1_x_joint" type ="revolute">
          <axis xyz="1 0 0"/>
          <limit effort="10000" lower ="-3.14" upper="3.14" velocity ="0.6"/>
          <origin rpy="0 0 0" xyz="0 0 0"/>
          <parent link="LeftHandPinky1_y_link"/>
          <child link="LeftHandPinky1_x_link"/>
      </joint>
      <link name="LeftHandPinky1endsite_z_link"/>
      <link name="LeftHandPinky1endsite_y_link"/>
      <link name="LeftHandPinky1endsite_x_link">
        <visual>
          <origin rpy="0 0 0" xyz="0 0 0"/>
          <geometry>
            <mesh filename="../rami/modelinria/LeftHandPinky1endsite.obj"/>
          </geometry>
          <material name="Blue"/>
        </visual>
        <collision>
          <origin rpy="0 0 0" xyz="0 0 0"/>
          <geometry>
            <mesh filename="../rami/modelinria/LeftHandPinky1endsite.obj"/>
          </geometry>
        </collision>
      </link>
      <joint name="LeftHandPinky1endsite_z_joint" type ="revolute">
          <axis xyz="0 0 1"/>
          <limit effort="10000" lower ="-3.14" upper="3.14" velocity ="0.6"/>
          <origin rpy="0 0 0" xyz="-0.19685 0 0"/>
          <parent link="LeftHandPinky1_x_link"/>
          <child link="LeftHandPinky1endsite_z_link"/>
      </joint>
      <joint name="LeftHandPinky1endsite_y_joint" type ="revolute">
          <axis xyz="0 1 0"/>
          <limit effort="10000" lower ="-3.14" upper="3.14" velocity ="0.6"/>
          <origin rpy="0 0 0" xyz="0 0 0"/>
          <parent link="LeftHandPinky1endsite_z_link"/>
          <child link="LeftHandPinky1endsite_y_link"/>
      </joint>
      <joint name="LeftHandPinky1endsite_x_joint" type ="revolute">
          <axis xyz="1 0 0"/>
          <limit effort="10000" lower ="-3.14" upper="3.14" velocity ="0.6"/>
          <origin rpy="0 0 0" xyz="0 0 0"/>
          <parent link="LeftHandPinky1endsite_y_link"/>
          <child link="LeftHandPinky1endsite_x_link"/>
      </joint>
      <link name="LeftHandIndex1_z_link"/>
      <link name="LeftHandIndex1_y_link"/>
      <link name="LeftHandIndex1_x_link">
        <visual>
          <origin rpy="0 0 0" xyz="0 0 0"/>
          <geometry>
            <mesh filename="../rami/modelinria/LeftHandIndex1.obj"/>
          </geometry>
          <material name="Blue"/>
        </visual>
        <collision>
          <origin rpy="0 0 0" xyz="0 0 0"/>
          <geometry>
            <mesh filename="../rami/modelinria/LeftHandIndex1.obj"/>
          </geometry>
        </collision>
      </link>
      <joint name="LeftHandIndex1_z_joint" type ="revolute">
          <axis xyz="0 0 1"/>
          <limit effort="10000" lower ="-3.14" upper="3.14" velocity ="0.6"/>
          <origin rpy="0 0 0" xyz="-0.414743 0.013815 0"/>
          <parent link="LeftHand_x_link"/>
          <child link="LeftHandIndex1_z_link"/>
      </joint>
      <joint name="LeftHandIndex1_y_joint" type ="revolute">
          <axis xyz="0 1 0"/>
          <limit effort="10000" lower ="-3.14" upper="3.14" velocity ="0.6"/>
          <origin rpy="0 0 0" xyz="0 0 0"/>
          <parent link="LeftHandIndex1_z_link"/>
          <child link="LeftHandIndex1_y_link"/>
      </joint>
      <joint name="LeftHandIndex1_x_joint" type ="revolute">
          <axis xyz="1 0 0"/>
          <limit effort="10000" lower ="-3.14" upper="3.14" velocity ="0.6"/>
          <origin rpy="0 0 0" xyz="0 0 0"/>
          <parent link="LeftHandIndex1_y_link"/>
          <child link="LeftHandIndex1_x_link"/>
      </joint>
      <link name="LeftHandIndex1endsite_z_link"/>
      <link name="LeftHandIndex1endsite_y_link"/>
      <link name="LeftHandIndex1endsite_x_link">
        <visual>
          <origin rpy="0 0 0" xyz="0 0 0"/>
          <geometry>
            <mesh filename="../rami/modelinria/LeftHandIndex1endsite.obj"/>
          </geometry>
          <material name="Blue"/>
        </visual>
        <collision>
          <origin rpy="0 0 0" xyz="0 0 0"/>
          <geometry>
            <mesh filename="../rami/modelinria/LeftHandIndex1endsite.obj"/>
          </geometry>
        </collision>
      </link>
      <joint name="LeftHandIndex1endsite_z_joint" type ="revolute">
          <axis xyz="0 0 1"/>
          <limit effort="10000" lower ="-3.14" upper="3.14" velocity ="0.6"/>
          <origin rpy="0 0 0" xyz="-0.23622 0 0"/>
          <parent link="LeftHandIndex1_x_link"/>
          <child link="LeftHandIndex1endsite_z_link"/>
      </joint>
      <joint name="LeftHandIndex1endsite_y_joint" type ="revolute">
          <axis xyz="0 1 0"/>
          <limit effort="10000" lower ="-3.14" upper="3.14" velocity ="0.6"/>
          <origin rpy="0 0 0" xyz="0 0 0"/>
          <parent link="LeftHandIndex1endsite_z_link"/>
          <child link="LeftHandIndex1endsite_y_link"/>
      </joint>
      <joint name="LeftHandIndex1endsite_x_joint" type ="revolute">
          <axis xyz="1 0 0"/>
          <limit effort="10000" lower ="-3.14" upper="3.14" velocity ="0.6"/>
          <origin rpy="0 0 0" xyz="0 0 0"/>
          <parent link="LeftHandIndex1endsite_y_link"/>
          <child link="LeftHandIndex1endsite_x_link"/>
      </joint>
      <link name="RightShoulder_z_link"/>
      <link name="RightShoulder_y_link"/>
      <link name="RightShoulder_x_link">
        <visual>
          <origin rpy="0 0 0" xyz="0 0 0"/>
          <geometry>
            <mesh filename="../rami/modelinria/RightShoulder.obj"/>
          </geometry>
          <material name="Blue"/>
        </visual>
        <collision>
          <origin rpy="0 0 0" xyz="0 0 0"/>
          <geometry>
            <mesh filename="../rami/modelinria/RightShoulder.obj"/>
          </geometry>
        </collision>
      </link>
      <joint name="RightShoulder_z_joint" type ="revolute">
          <axis xyz="0 0 1"/>
          <limit effort="10000" lower ="-3.14" upper="3.14" velocity ="0.6"/>
          <origin rpy="0 0 0" xyz="0 0 1.25984"/>
          <parent link="Spine_x_link"/>
          <child link="RightShoulder_z_link"/>
      </joint>
      <joint name="RightShoulder_y_joint" type ="revolute">
          <axis xyz="0 1 0"/>
          <limit effort="10000" lower ="-3.14" upper="3.14" velocity ="0.6"/>
          <origin rpy="0 0 0" xyz="0 0 0"/>
          <parent link="RightShoulder_z_link"/>
          <child link="RightShoulder_y_link"/>
      </joint>
      <joint name="RightShoulder_x_joint" type ="revolute">
          <axis xyz="1 0 0"/>
          <limit effort="10000" lower ="-3.14" upper="3.14" velocity ="0.6"/>
          <origin rpy="0 0 0" xyz="0 0 0"/>
          <parent link="RightShoulder_y_link"/>
          <child link="RightShoulder_x_link"/>
      </joint>
      <link name="RightArm_z_link"/>
      <link name="RightArm_y_link"/>
      <link name="RightArm_x_link">
        <visual>
          <origin rpy="0 0 0" xyz="0 0 0"/>
          <geometry>
            <mesh filename="../rami/modelinria/RightArm.obj"/>
          </geometry>
          <material name="Blue"/>
        </visual>
        <collision>
          <origin rpy="0 0 0" xyz="0 0 0"/>
          <geometry>
            <mesh filename="../rami/modelinria/RightArm.obj"/>
          </geometry>
        </collision>
      </link>
      <joint name="RightArm_z_joint" type ="revolute">
          <axis xyz="0 0 1"/>
          <limit effort="10000" lower ="-3.14" upper="3.14" velocity ="0.6"/>
          <origin rpy="0 0 0" xyz="0.7874 0 0"/>
          <parent link="RightShoulder_x_link"/>
          <child link="RightArm_z_link"/>
      </joint>
      <joint name="RightArm_y_joint" type ="revolute">
          <axis xyz="0 1 0"/>
          <limit effort="10000" lower ="-3.14" upper="3.14" velocity ="0.6"/>
          <origin rpy="0 0 0" xyz="0 0 0"/>
          <parent link="RightArm_z_link"/>
          <child link="RightArm_y_link"/>
      </joint>
      <joint name="RightArm_x_joint" type ="revolute">
          <axis xyz="1 0 0"/>
          <limit effort="10000" lower ="-3.14" upper="3.14" velocity ="0.6"/>
          <origin rpy="0 0 0" xyz="0 0 0"/>
          <parent link="RightArm_y_link"/>
          <child link="RightArm_x_link"/>
      </joint>
      <link name="RightForeArm_z_link"/>
      <link name="RightForeArm_y_link"/>
      <link name="RightForeArm_x_link">
        <visual>
          <origin rpy="0 0 0" xyz="0 0 0"/>
          <geometry>
            <mesh filename="../rami/modelinria/RightForeArm.obj"/>
          </geometry>
          <material name="Blue"/>
        </visual>
        <collision>
          <origin rpy="0 0 0" xyz="0 0 0"/>
          <geometry>
            <mesh filename="../rami/modelinria/RightForeArm.obj"/>
          </geometry>
        </collision>
      </link>
      <joint name="RightForeArm_z_joint" type ="revolute">
          <axis xyz="0 0 1"/>
          <limit effort="10000" lower ="-3.14" upper="3.14" velocity ="0.6"/>
          <origin rpy="0 0 0" xyz="1.29921 0 0"/>
          <parent link="RightArm_x_link"/>
          <child link="RightForeArm_z_link"/>
      </joint>
      <joint name="RightForeArm_y_joint" type ="revolute">
          <axis xyz="0 1 0"/>
          <limit effort="10000" lower ="-3.14" upper="3.14" velocity ="0.6"/>
          <origin rpy="0 0 0" xyz="0 0 0"/>
          <parent link="RightForeArm_z_link"/>
          <child link="RightForeArm_y_link"/>
      </joint>
      <joint name="RightForeArm_x_joint" type ="revolute">
          <axis xyz="1 0 0"/>
          <limit effort="10000" lower ="-3.14" upper="3.14" velocity ="0.6"/>
          <origin rpy="0 0 0" xyz="0 0 0"/>
          <parent link="RightForeArm_y_link"/>
          <child link="RightForeArm_x_link"/>
      </joint>
      <link name="RightHand_z_link"/>
      <link name="RightHand_y_link"/>
      <link name="RightHand_x_link">
        <visual>
          <origin rpy="0 0 0" xyz="0 0 0"/>
          <geometry>
            <mesh filename="../rami/modelinria/RightHand.obj"/>
          </geometry>
          <material name="Blue"/>
        </visual>
        <collision>
          <origin rpy="0 0 0" xyz="0 0 0"/>
          <geometry>
            <mesh filename="../rami/modelinria/RightHand.obj"/>
          </geometry>
        </collision>
      </link>
      <joint name="RightHand_z_joint" type ="revolute">
          <axis xyz="0 0 1"/>
          <limit effort="10000" lower ="-3.14" upper="3.14" velocity ="0.6"/>
          <origin rpy="0 0 0" xyz="1.03081 0 0"/>
          <parent link="RightForeArm_x_link"/>
          <child link="RightHand_z_link"/>
      </joint>
      <joint name="RightHand_y_joint" type ="revolute">
          <axis xyz="0 1 0"/>
          <limit effort="10000" lower ="-3.14" upper="3.14" velocity ="0.6"/>
          <origin rpy="0 0 0" xyz="0 0 0"/>
          <parent link="RightHand_z_link"/>
          <child link="RightHand_y_link"/>
      </joint>
      <joint name="RightHand_x_joint" type ="revolute">
          <axis xyz="1 0 0"/>
          <limit effort="10000" lower ="-3.14" upper="3.14" velocity ="0.6"/>
          <origin rpy="0 0 0" xyz="0 0 0"/>
          <parent link="RightHand_y_link"/>
          <child link="RightHand_x_link"/>
      </joint>
      <link name="RightHandPinky1_z_link"/>
      <link name="RightHandPinky1_y_link"/>
      <link name="RightHandPinky1_x_link">
        <visual>
          <origin rpy="0 0 0" xyz="0 0 0"/>
          <geometry>
            <mesh filename="../rami/modelinria/RightHandPinky1.obj"/>
          </geometry>
          <material name="Blue"/>
        </visual>
        <collision>
          <origin rpy="0 0 0" xyz="0 0 0"/>
          <geometry>
            <mesh filename="../rami/modelinria/RightHandPinky1.obj"/>
          </geometry>
        </collision>
      </link>
      <joint name="RightHandPinky1_z_joint" type ="revolute">
          <axis xyz="0 0 1"/>
          <limit effort="10000" lower ="-3.14" upper="3.14" velocity ="0.6"/>
          <origin rpy="0 0 0" xyz="0.294832 -0.017528 0"/>
          <parent link="RightHand_x_link"/>
          <child link="RightHandPinky1_z_link"/>
      </joint>
      <joint name="RightHandPinky1_y_joint" type ="revolute">
          <axis xyz="0 1 0"/>
          <limit effort="10000" lower ="-3.14" upper="3.14" velocity ="0.6"/>
          <origin rpy="0 0 0" xyz="0 0 0"/>
          <parent link="RightHandPinky1_z_link"/>
          <child link="RightHandPinky1_y_link"/>
      </joint>
      <joint name="RightHandPinky1_x_joint" type ="revolute">
          <axis xyz="1 0 0"/>
          <limit effort="10000" lower ="-3.14" upper="3.14" velocity ="0.6"/>
          <origin rpy="0 0 0" xyz="0 0 0"/>
          <parent link="RightHandPinky1_y_link"/>
          <child link="RightHandPinky1_x_link"/>
      </joint>
      <link name="RightHandPinky1endsite_z_link"/>
      <link name="RightHandPinky1endsite_y_link"/>
      <link name="RightHandPinky1endsite_x_link">
        <visual>
          <origin rpy="0 0 0" xyz="0 0 0"/>
          <geometry>
            <mesh filename="../rami/modelinria/RightHandPinky1endsite.obj"/>
          </geometry>
          <material name="Blue"/>
        </visual>
        <collision>
          <origin rpy="0 0 0" xyz="0 0 0"/>
          <geometry>
            <mesh filename="../rami/modelinria/RightHandPinky1endsite.obj"/>
          </geometry>
        </collision>
      </link>
      <joint name="RightHandPinky1endsite_z_joint" type ="revolute">
          <axis xyz="0 0 1"/>
          <limit effort="10000" lower ="-3.14" upper="3.14" velocity ="0.6"/>
          <origin rpy="0 0 0" xyz="0.19685 0 0"/>
          <parent link="RightHandPinky1_x_link"/>
          <child link="RightHandPinky1endsite_z_link"/>
      </joint>
      <joint name="RightHandPinky1endsite_y_joint" type ="revolute">
          <axis xyz="0 1 0"/>
          <limit effort="10000" lower ="-3.14" upper="3.14" velocity ="0.6"/>
          <origin rpy="0 0 0" xyz="0 0 0"/>
          <parent link="RightHandPinky1endsite_z_link"/>
          <child link="RightHandPinky1endsite_y_link"/>
      </joint>
      <joint name="RightHandPinky1endsite_x_joint" type ="revolute">
          <axis xyz="1 0 0"/>
          <limit effort="10000" lower ="-3.14" upper="3.14" velocity ="0.6"/>
          <origin rpy="0 0 0" xyz="0 0 0"/>
          <parent link="RightHandPinky1endsite_y_link"/>
          <child link="RightHandPinky1endsite_x_link"/>
      </joint>
      <link name="RightHandIndex1_z_link"/>
      <link name="RightHandIndex1_y_link"/>
      <link name="RightHandIndex1_x_link">
        <visual>
          <origin rpy="0 0 0" xyz="0 0 0"/>
          <geometry>
            <mesh filename="../rami/modelinria/RightHandIndex1.obj"/>
          </geometry>
          <material name="Blue"/>
        </visual>
        <collision>
          <origin rpy="0 0 0" xyz="0 0 0"/>
          <geometry>
            <mesh filename="../rami/modelinria/RightHandIndex1.obj"/>
          </geometry>
        </collision>
      </link>
      <joint name="RightHandIndex1_z_joint" type ="revolute">
          <axis xyz="0 0 1"/>
          <limit effort="10000" lower ="-3.14" upper="3.14" velocity ="0.6"/>
          <origin rpy="0 0 0" xyz="0.346188 0.017528 0"/>
          <parent link="RightHand_x_link"/>
          <child link="RightHandIndex1_z_link"/>
      </joint>
      <joint name="RightHandIndex1_y_joint" type ="revolute">
          <axis xyz="0 1 0"/>
          <limit effort="10000" lower ="-3.14" upper="3.14" velocity ="0.6"/>
          <origin rpy="0 0 0" xyz="0 0 0"/>
          <parent link="RightHandIndex1_z_link"/>
          <child link="RightHandIndex1_y_link"/>
      </joint>
      <joint name="RightHandIndex1_x_joint" type ="revolute">
          <axis xyz="1 0 0"/>
          <limit effort="10000" lower ="-3.14" upper="3.14" velocity ="0.6"/>
          <origin rpy="0 0 0" xyz="0 0 0"/>
          <parent link="RightHandIndex1_y_link"/>
          <child link="RightHandIndex1_x_link"/>
      </joint>
      <link name="RightHandIndex1endsite_z_link"/>
      <link name="RightHandIndex1endsite_y_link"/>
      <link name="RightHandIndex1endsite_x_link">
        <visual>
          <origin rpy="0 0 0" xyz="0 0 0"/>
          <geometry>
            <mesh filename="../rami/modelinria/RightHandIndex1endsite.obj"/>
          </geometry>
          <material name="Blue"/>
        </visual>
        <collision>
          <origin rpy="0 0 0" xyz="0 0 0"/>
          <geometry>
            <mesh filename="../rami/modelinria/RightHandIndex1endsite.obj"/>
          </geometry>
        </collision>
      </link>
      <joint name="RightHandIndex1endsite_z_joint" type ="revolute">
          <axis xyz="0 0 1"/>
          <limit effort="10000" lower ="-3.14" upper="3.14" velocity ="0.6"/>
          <origin rpy="0 0 0" xyz="0.23622 0 0"/>
          <parent link="RightHandIndex1_x_link"/>
          <child link="RightHandIndex1endsite_z_link"/>
      </joint>
      <joint name="RightHandIndex1endsite_y_joint" type ="revolute">
          <axis xyz="0 1 0"/>
          <limit effort="10000" lower ="-3.14" upper="3.14" velocity ="0.6"/>
          <origin rpy="0 0 0" xyz="0 0 0"/>
          <parent link="RightHandIndex1endsite_z_link"/>
          <child link="RightHandIndex1endsite_y_link"/>
      </joint>
      <joint name="RightHandIndex1endsite_x_joint" type ="revolute">
          <axis xyz="1 0 0"/>
          <limit effort="10000" lower ="-3.14" upper="3.14" velocity ="0.6"/>
          <origin rpy="0 0 0" xyz="0 0 0"/>
          <parent link="RightHandIndex1endsite_y_link"/>
          <child link="RightHandIndex1endsite_x_link"/>
      </joint>
      <link name="LeftUpLeg_z_link"/>
      <link name="LeftUpLeg_y_link"/>
      <link name="LeftUpLeg_x_link">
        <visual>
          <origin rpy="0 0 0" xyz="0 0 0"/>
          <geometry>
            <mesh filename="../rami/modelinria/LeftUpLeg.obj"/>
          </geometry>
          <material name="Blue"/>
        </visual>
        <collision>
          <origin rpy="0 0 0" xyz="0 0 0"/>
          <geometry>
            <mesh filename="../rami/modelinria/LeftUpLeg.obj"/>
          </geometry>
        </collision>
      </link>
      <joint name="LeftUpLeg_z_joint" type ="revolute">
          <axis xyz="0 0 1"/>
          <limit effort="10000" lower ="-3.14" upper="3.14" velocity ="0.6"/>
          <origin rpy="0 0 0" xyz="-0.408853 0 0"/>
          <parent link="pelvis_link"/>
          <child link="LeftUpLeg_z_link"/>
      </joint>
      <joint name="LeftUpLeg_y_joint" type ="revolute">
          <axis xyz="0 1 0"/>
          <limit effort="10000" lower ="-3.14" upper="3.14" velocity ="0.6"/>
          <origin rpy="0 0 0" xyz="0 0 0"/>
          <parent link="LeftUpLeg_z_link"/>
          <child link="LeftUpLeg_y_link"/>
      </joint>
      <joint name="LeftUpLeg_x_joint" type ="revolute">
          <axis xyz="1 0 0"/>
          <limit effort="10000" lower ="-3.14" upper="3.14" velocity ="0.6"/>
          <origin rpy="0 0 0" xyz="0 0 0"/>
          <parent link="LeftUpLeg_y_link"/>
          <child link="LeftUpLeg_x_link"/>
      </joint>
      <link name="LeftLeg_z_link"/>
      <link name="LeftLeg_y_link"/>
      <link name="LeftLeg_x_link">
        <visual>
          <origin rpy="0 0 0" xyz="0 0 0"/>
          <geometry>
            <mesh filename="../rami/modelinria/LeftLeg.obj"/>
          </geometry>
          <material name="Blue"/>
        </visual>
        <collision>
          <origin rpy="0 0 0" xyz="0 0 0"/>
          <geometry>
            <mesh filename="../rami/modelinria/LeftLeg.obj"/>
          </geometry>
        </collision>
      </link>
      <joint name="LeftLeg_z_joint" type ="revolute">
          <axis xyz="0 0 1"/>
          <limit effort="10000" lower ="-3.14" upper="3.14" velocity ="0.6"/>
          <origin rpy="0 0 0" xyz="0 0 -1.73605"/>
          <parent link="LeftUpLeg_x_link"/>
          <child link="LeftLeg_z_link"/>
      </joint>
      <joint name="LeftLeg_y_joint" type ="revolute">
          <axis xyz="0 1 0"/>
          <limit effort="10000" lower ="-3.14" upper="3.14" velocity ="0.6"/>
          <origin rpy="0 0 0" xyz="0 0 0"/>
          <parent link="LeftLeg_z_link"/>
          <child link="LeftLeg_y_link"/>
      </joint>
      <joint name="LeftLeg_x_joint" type ="revolute">
          <axis xyz="1 0 0"/>
          <limit effort="10000" lower ="-3.14" upper="3.14" velocity ="0.6"/>
          <origin rpy="0 0 0" xyz="0 0 0"/>
          <parent link="LeftLeg_y_link"/>
          <child link="LeftLeg_x_link"/>
      </joint>
      <link name="LeftFoot_z_link"/>
      <link name="LeftFoot_y_link"/>
      <link name="LeftFoot_x_link">
        <visual>
          <origin rpy="0 0 0" xyz="0 0 0"/>
          <geometry>
            <mesh filename="../rami/modelinria/LeftFoot.obj"/>
          </geometry>
          <material name="Blue"/>
        </visual>
        <collision>
          <origin rpy="0 0 0" xyz="0 0 0"/>
          <geometry>
            <mesh filename="../rami/modelinria/LeftFoot.obj"/>
          </geometry>
        </collision>
      </link>
      <joint name="LeftFoot_z_joint" type ="revolute">
          <axis xyz="0 0 1"/>
          <limit effort="10000" lower ="-3.14" upper="3.14" velocity ="0.6"/>
          <origin rpy="0 0 0" xyz="0 0 -1.61351"/>
          <parent link="LeftLeg_x_link"/>
          <child link="LeftFoot_z_link"/>
      </joint>
      <joint name="LeftFoot_y_joint" type ="revolute">
          <axis xyz="0 1 0"/>
          <limit effort="10000" lower ="-3.14" upper="3.14" velocity ="0.6"/>
          <origin rpy="0 0 0" xyz="0 0 0"/>
          <parent link="LeftFoot_z_link"/>
          <child link="LeftFoot_y_link"/>
      </joint>
      <joint name="LeftFoot_x_joint" type ="revolute">
          <axis xyz="1 0 0"/>
          <limit effort="10000" lower ="-3.14" upper="3.14" velocity ="0.6"/>
          <origin rpy="0 0 0" xyz="0 0 0"/>
          <parent link="LeftFoot_y_link"/>
          <child link="LeftFoot_x_link"/>
      </joint>
      <link name="LeftToeBase_z_link"/>
      <link name="LeftToeBase_y_link"/>
      <link name="LeftToeBase_x_link">
        <visual>
          <origin rpy="0 0 0" xyz="0 0 0"/>
          <geometry>
            <mesh filename="../rami/modelinria/LeftToeBase.obj"/>
          </geometry>
          <material name="Blue"/>
        </visual>
        <collision>
          <origin rpy="0 0 0" xyz="0 0 0"/>
          <geometry>
            <mesh filename="../rami/modelinria/LeftToeBase.obj"/>
          </geometry>
        </collision>
      </link>
      <joint name="LeftToeBase_z_joint" type ="revolute">
          <axis xyz="0 0 1"/>
          <limit effort="10000" lower ="-3.14" upper="3.14" velocity ="0.6"/>
          <origin rpy="0 0 0" xyz="0 0.510779 -0.136863"/>
          <parent link="LeftFoot_x_link"/>
          <child link="LeftToeBase_z_link"/>
      </joint>
      <joint name="LeftToeBase_y_joint" type ="revolute">
          <axis xyz="0 1 0"/>
          <limit effort="10000" lower ="-3.14" upper="3.14" velocity ="0.6"/>
          <origin rpy="0 0 0" xyz="0 0 0"/>
          <parent link="LeftToeBase_z_link"/>
          <child link="LeftToeBase_y_link"/>
      </joint>
      <joint name="LeftToeBase_x_joint" type ="revolute">
          <axis xyz="1 0 0"/>
          <limit effort="10000" lower ="-3.14" upper="3.14" velocity ="0.6"/>
          <origin rpy="0 0 0" xyz="0 0 0"/>
          <parent link="LeftToeBase_y_link"/>
          <child link="LeftToeBase_x_link"/>
      </joint>
      <link name="LeftToeBaseendsite_z_link"/>
      <link name="LeftToeBaseendsite_y_link"/>
      <link name="LeftToeBaseendsite_x_link">
        <visual>
          <origin rpy="0 0 0" xyz="0 0 0"/>
          <geometry>
            <mesh filename="../rami/modelinria/LeftToeBaseendsite.obj"/>
          </geometry>
          <material name="Blue"/>
        </visual>
        <collision>
          <origin rpy="0 0 0" xyz="0 0 0"/>
          <geometry>
            <mesh filename="../rami/modelinria/LeftToeBaseendsite.obj"/>
          </geometry>
        </collision>
      </link>
      <joint name="LeftToeBaseendsite_z_joint" type ="revolute">
          <axis xyz="0 0 1"/>
          <limit effort="10000" lower ="-3.14" upper="3.14" velocity ="0.6"/>
          <origin rpy="0 0 0" xyz="0 0.177165 0"/>
          <parent link="LeftToeBase_x_link"/>
          <child link="LeftToeBaseendsite_z_link"/>
      </joint>
      <joint name="LeftToeBaseendsite_y_joint" type ="revolute">
          <axis xyz="0 1 0"/>
          <limit effort="10000" lower ="-3.14" upper="3.14" velocity ="0.6"/>
          <origin rpy="0 0 0" xyz="0 0 0"/>
          <parent link="LeftToeBaseendsite_z_link"/>
          <child link="LeftToeBaseendsite_y_link"/>
      </joint>
      <joint name="LeftToeBaseendsite_x_joint" type ="revolute">
          <axis xyz="1 0 0"/>
          <limit effort="10000" lower ="-3.14" upper="3.14" velocity ="0.6"/>
          <origin rpy="0 0 0" xyz="0 0 0"/>
          <parent link="LeftToeBaseendsite_y_link"/>
          <child link="LeftToeBaseendsite_x_link"/>
      </joint>
      <link name="RightUpLeg_z_link"/>
      <link name="RightUpLeg_y_link"/>
      <link name="RightUpLeg_x_link">
        <visual>
          <origin rpy="0 0 0" xyz="0 0 0"/>
          <geometry>
            <mesh filename="../rami/modelinria/RightUpLeg.obj"/>
          </geometry>
          <material name="Blue"/>
        </visual>
        <collision>
          <origin rpy="0 0 0" xyz="0 0 0"/>
          <geometry>
            <mesh filename="../rami/modelinria/RightUpLeg.obj"/>
          </geometry>
        </collision>
      </link>
      <joint name="RightUpLeg_z_joint" type ="revolute">
          <axis xyz="0 0 1"/>
          <limit effort="10000" lower ="-3.14" upper="3.14" velocity ="0.6"/>
          <origin rpy="0 0 0" xyz="0.408853 0 0"/>
          <parent link="pelvis_link"/>
          <child link="RightUpLeg_z_link"/>
      </joint>
      <joint name="RightUpLeg_y_joint" type ="revolute">
          <axis xyz="0 1 0"/>
          <limit effort="10000" lower ="-3.14" upper="3.14" velocity ="0.6"/>
          <origin rpy="0 0 0" xyz="0 0 0"/>
          <parent link="RightUpLeg_z_link"/>
          <child link="RightUpLeg_y_link"/>
      </joint>
      <joint name="RightUpLeg_x_joint" type ="revolute">
          <axis xyz="1 0 0"/>
          <limit effort="10000" lower ="-3.14" upper="3.14" velocity ="0.6"/>
          <origin rpy="0 0 0" xyz="0 0 0"/>
          <parent link="RightUpLeg_y_link"/>
          <child link="RightUpLeg_x_link"/>
      </joint>
      <link name="RightLeg_z_link"/>
      <link name="RightLeg_y_link"/>
      <link name="RightLeg_x_link">
        <visual>
          <origin rpy="0 0 0" xyz="0 0 0"/>
          <geometry>
            <mesh filename="../rami/modelinria/RightLeg.obj"/>
          </geometry>
          <material name="Blue"/>
        </visual>
        <collision>
          <origin rpy="0 0 0" xyz="0 0 0"/>
          <geometry>
            <mesh filename="../rami/modelinria/RightLeg.obj"/>
          </geometry>
        </collision>
      </link>
      <joint name="RightLeg_z_joint" type ="revolute">
          <axis xyz="0 0 1"/>
          <limit effort="10000" lower ="-3.14" upper="3.14" velocity ="0.6"/>
          <origin rpy="0 0 0" xyz="0 0 -1.73605"/>
          <parent link="RightUpLeg_x_link"/>
          <child link="RightLeg_z_link"/>
      </joint>
      <joint name="RightLeg_y_joint" type ="revolute">
          <axis xyz="0 1 0"/>
          <limit effort="10000" lower ="-3.14" upper="3.14" velocity ="0.6"/>
          <origin rpy="0 0 0" xyz="0 0 0"/>
          <parent link="RightLeg_z_link"/>
          <child link="RightLeg_y_link"/>
      </joint>
      <joint name="RightLeg_x_joint" type ="revolute">
          <axis xyz="1 0 0"/>
          <limit effort="10000" lower ="-3.14" upper="3.14" velocity ="0.6"/>
          <origin rpy="0 0 0" xyz="0 0 0"/>
          <parent link="RightLeg_y_link"/>
          <child link="RightLeg_x_link"/>
      </joint>
      <link name="RightFoot_z_link"/>
      <link name="RightFoot_y_link"/>
      <link name="RightFoot_x_link">
        <visual>
          <origin rpy="0 0 0" xyz="0 0 0"/>
          <geometry>
            <mesh filename="../rami/modelinria/RightFoot.obj"/>
          </geometry>
          <material name="Blue"/>
        </visual>
        <collision>
          <origin rpy="0 0 0" xyz="0 0 0"/>
          <geometry>
            <mesh filename="../rami/modelinria/RightFoot.obj"/>
          </geometry>
        </collision>
      </link>
      <joint name="RightFoot_z_joint" type ="revolute">
          <axis xyz="0 0 1"/>
          <limit effort="10000" lower ="-3.14" upper="3.14" velocity ="0.6"/>
          <origin rpy="0 0 0" xyz="0 0 -1.61351"/>
          <parent link="RightLeg_x_link"/>
          <child link="RightFoot_z_link"/>
      </joint>
      <joint name="RightFoot_y_joint" type ="revolute">
          <axis xyz="0 1 0"/>
          <limit effort="10000" lower ="-3.14" upper="3.14" velocity ="0.6"/>
          <origin rpy="0 0 0" xyz="0 0 0"/>
          <parent link="RightFoot_z_link"/>
          <child link="RightFoot_y_link"/>
      </joint>
      <joint name="RightFoot_x_joint" type ="revolute">
          <axis xyz="1 0 0"/>
          <limit effort="10000" lower ="-3.14" upper="3.14" velocity ="0.6"/>
          <origin rpy="0 0 0" xyz="0 0 0"/>
          <parent link="RightFoot_y_link"/>
          <child link="RightFoot_x_link"/>
      </joint>
      <link name="RightToeBase_z_link"/>
      <link name="RightToeBase_y_link"/>
      <link name="RightToeBase_x_link">
        <visual>
          <origin rpy="0 0 0" xyz="0 0 0"/>
          <geometry>
            <mesh filename="../rami/modelinria/RightToeBase.obj"/>
          </geometry>
          <material name="Blue"/>
        </visual>
        <collision>
          <origin rpy="0 0 0" xyz="0 0 0"/>
          <geometry>
            <mesh filename="../rami/modelinria/RightToeBase.obj"/>
          </geometry>
        </collision>
      </link>
      <joint name="RightToeBase_z_joint" type ="revolute">
          <axis xyz="0 0 1"/>
          <limit effort="10000" lower ="-3.14" upper="3.14" velocity ="0.6"/>
          <origin rpy="0 0 0" xyz="0 0.510779 -0.136863"/>
          <parent link="RightFoot_x_link"/>
          <child link="RightToeBase_z_link"/>
      </joint>
      <joint name="RightToeBase_y_joint" type ="revolute">
          <axis xyz="0 1 0"/>
          <limit effort="10000" lower ="-3.14" upper="3.14" velocity ="0.6"/>
          <origin rpy="0 0 0" xyz="0 0 0"/>
          <parent link="RightToeBase_z_link"/>
          <child link="RightToeBase_y_link"/>
      </joint>
      <joint name="RightToeBase_x_joint" type ="revolute">
          <axis xyz="1 0 0"/>
          <limit effort="10000" lower ="-3.14" upper="3.14" velocity ="0.6"/>
          <origin rpy="0 0 0" xyz="0 0 0"/>
          <parent link="RightToeBase_y_link"/>
          <child link="RightToeBase_x_link"/>
      </joint>
      <link name="RightToeBaseendsite_z_link"/>
      <link name="RightToeBaseendsite_y_link"/>
      <link name="RightToeBaseendsite_x_link">
        <visual>
          <origin rpy="0 0 0" xyz="0 0 0"/>
          <geometry>
            <mesh filename="../rami/modelinria/RightToeBaseendsite.obj"/>
          </geometry>
          <material name="Blue"/>
        </visual>
        <collision>
          <origin rpy="0 0 0" xyz="0 0 0"/>
          <geometry>
            <mesh filename="../rami/modelinria/RightToeBaseendsite.obj"/>
          </geometry>
        </collision>
      </link>
      <joint name="RightToeBaseendsite_z_joint" type ="revolute">
          <axis xyz="0 0 1"/>
          <limit effort="10000" lower ="-3.14" upper="3.14" velocity ="0.6"/>
          <origin rpy="0 0 0" xyz="0 0.177165 0"/>
          <parent link="RightToeBase_x_link"/>
          <child link="RightToeBaseendsite_z_link"/>
      </joint>
      <joint name="RightToeBaseendsite_y_joint" type ="revolute">
          <axis xyz="0 1 0"/>
          <limit effort="10000" lower ="-3.14" upper="3.14" velocity ="0.6"/>
          <origin rpy="0 0 0" xyz="0 0 0"/>
          <parent link="RightToeBaseendsite_z_link"/>
          <child link="RightToeBaseendsite_y_link"/>
      </joint>
      <joint name="RightToeBaseendsite_x_joint" type ="revolute">
          <axis xyz="1 0 0"/>
          <limit effort="10000" lower ="-3.14" upper="3.14" velocity ="0.6"/>
          <origin rpy="0 0 0" xyz="0 0 0"/>
          <parent link="RightToeBaseendsite_y_link"/>
          <child link="RightToeBaseendsite_x_link"/>
      </joint>

</robot>
